Workbook

Sheet 项目信息
A1: =T(B22)
A2: =T(B23)
A4: 工程信息
A5: 项目名称 | B5: DEMO-C项目C | E5: 项目编号
A6: 描述 | E6: 报价交期
A7: 报价单号 | B7: DEMO-QUOTE
A8: 报价人 | B8: 报价员A
A9: 创建日期 | B9: 2026.02.02
A10: 报价审核人
A11: 项目负责人
A12: 项目备注
A13: 客户信息
A14: 客户名称
A15: 联系人
A16: 联系电话
A17: 客户地址
A18: 客户邮编
A19: 客户网址
A20: 客户email
A21: 本企业信息
A22: 单位名称 | B22: 某成套设备有限公司
A23: 英文名称 | B23: Anonymized Switchgear Co.,Ltd
A24: 联系人 | B24: 宋楠
A25: 联系电话 | B25: 6.9198511e+09
A26: 销售地区 | B26: 全国
A27: 分类汇总 金额单位：人民币元
A28: 序号 | B28: 分类名称 | C28: 箱柜数量 | D28: 总 价 | E28: 成本 | F28: 毛利 | G28: 毛利率 | H28: 分类属性
A29: =ROW()-ROW(A$28) | B29: =MID(CELL("filename",folderTablee32ba25eda8d4a59a0a0201137327f11),SEARCH({"xlsx]",".xls]"},CELL("filename",folderTablee32ba25eda8d4a59a0a0201137327f11))+5,31) | C29: =IF(H29="箱变",低压柜!F107,低压柜!F103*IF(低压柜!F107="",1,低压柜!F107)) | D29: =ROUND(低压柜!H107,2) | E29: =ROUND(低压柜!J107,2) | F29: =ROUND((D29-E29),2) | G29: =IF(D29=0,0,F29/D29) | H29: =IF(OR(ISNUMBER(FIND("箱变",B29))=TRUE,ISNUMBER(FIND("欧变",B29))=TRUE,ISNUMBER(FIND("美变",B29))=TRUE,ISNUMBER(FIND("KVA",UPPER(B29)))=TRUE,ISNUMBER(FIND("箱式变电",B29))=TRUE),"箱变","常规")
A30: =ROW()-ROW(A$28)
A31: =ROW()-ROW(A$28)
A32: =ROW()-ROW(A$28)
A33: =ROW()-ROW(A$28)
A34: =ROW()-ROW(A$28)
A35: =ROW()-ROW(A$28)
A36: =ROW()-ROW(A$28)
A37: =ROW()-ROW(A$28)
A38: =ROW()-ROW(A$28)
A39: =ROW()-ROW(A$28)
A40: =ROW()-ROW(A$28)
A41: =ROW()-ROW(A$28)
...

Sheet 低压柜
A2: =T(项目信息!B22)
A3: =T(项目信息!B23)
A4: 成套产品报价清单 金额单位：人民币元
A5: =CONCATENATE("项目名称:",项目信息!B5) | H5: =CONCATENATE("报价序号:",项目信息!B7)
A6: 序号 | B6: 柜号 | C6: 箱柜名称 | D6: 箱柜型号 | E6: 单位 | F6: 数量 | G6: 单 价 | H6: 总 价 | I6: 备注 | J6: 成本总价 | K6: 毛利 | L6: 毛利率 | M6: 箱柜尺寸 | N6: 类别 | O6: 预留 | P6: 预留 | Q6: 图号
A7: =ROW()-ROW(A$6) | B7: AAN1-01、BAN2-01 | C7: 进线柜 | D7: BlokSeT | E7: 台 | F7: 2 | G7: =ROUND(H143,2) | H7: =ROUND(F7*G7,2) | J7: =ROUND(K144,2) | K7: =ROUND(H7-J7,2) | L7: =IF(H7=0,0,K7/H7) | M7: 1200W*1200D*2200H | N7: 低压固定柜
A8: =ROW()-ROW(A$6) | B8: AAN1-02、BAN2-02 | C8: 联络柜 | D8: BlokSeT | E8: 台 | F8: 2 | G8: =ROUND(H172,2) | H8: =ROUND(F8*G8,2) | J8: =ROUND(K173,2) | K8: =ROUND(H8-J8,2) | L8: =IF(H8=0,0,K8/H8) | M8: 700W*1200D*2200H | N8: 低压固定柜
A9: =ROW()-ROW(A$6) | B9: AAN1-03-1、BAN2-03-1 | C9: 电容柜 | D9: BlokSeT | E9: 台 | F9: 2 | G9: =ROUND(H200,2) | H9: =ROUND(F9*G9,2) | J9: =ROUND(K201,2) | K9: =ROUND(H9-J9,2) | L9: =IF(H9=0,0,K9/H9) | M9: 800W*1200D*2200H | N9: 低压固定柜
A10: =ROW()-ROW(A$6) | B10: AAN1-03-2、BAN2-03-2 | C10: 电容柜 | D10: BlokSeT | E10: 台 | F10: 2 | G10: =ROUND(H228,2) | H10: =ROUND(F10*G10,2) | J10: =ROUND(K229,2) | K10: =ROUND(H10-J10,2) | L10: =IF(H10=0,0,K10/H10) | M10: 800W*1200D*2200H | N10: 低压固定柜
A11: =ROW()-ROW(A$6) | B11: AAN1-04、BAN2-04 | C11: 有源滤波柜 | D11: BlokSeT | E11: 台 | F11: 2 | G11: =ROUND(H255,2) | H11: =ROUND(F11*G11,2) | J11: =ROUND(K256,2) | K11: =ROUND(H11-J11,2) | L11: =IF(H11=0,0,K11/H11) | M11: 800W*1200D*2200H | N11: 低压固定柜
A12: =ROW()-ROW(A$6) | B12: AAN1-05、BAN2-05 | C12: 馈线柜 | D12: BlokSeT | E12: 台 | F12: 2 | G12: =ROUND(H286,2) | H12: =ROUND(F12*G12,2) | J12: =ROUND(K287,2) | K12: =ROUND(H12-J12,2) | L12: =IF(H12=0,0,K12/H12) | M12: 800W*1200D*2200H | N12: 低压固定柜
A13: =ROW()-ROW(A$6) | B13: AAN1-06、BAN2-06 | C13: 馈线柜 | D13: BlokSeT | E13: 台 | F13: 2 | G13: =ROUND(H317,2) | H13: =ROUND(F13*G13,2) | J13: =ROUND(K318,2) | K13: =ROUND(H13-J13,2) | L13: =IF(H13=0,0,K13/H13) | M13: 800W*1200D*2200H | N13: 低压固定柜
A14: =ROW()-ROW(A$6) | B14: AAN1-07 | C14: 馈线柜 | D14: BlokSeT | E14: 台 | F14: 1 | G14: =ROUND(H350,2) | H14: =ROUND(F14*G14,2) | J14: =ROUND(K351,2) | K14: =ROUND(H14-J14,2) | L14: =IF(H14=0,0,K14/H14) | M14: 800W*1200D*2200H | N14: 低压固定柜
A15: =ROW()-ROW(A$6) | B15: AAN1-08 | C15: 馈线柜 | D15: BlokSeT | E15: 台 | F15: 1 | G15: =ROUND(H382,2) | H15: =ROUND(F15*G15,2) | J15: =ROUND(K383,2) | K15: =ROUND(H15-J15,2) | L15: =IF(H15=0,0,K15/H15) | M15: 600W*1200D*2200H | N15: 低压固定柜
A16: =ROW()-ROW(A$6) | B16: AAN1-09 | C16: 馈线柜 | D16: BlokSeT | E16: 台 | F16: 1 | G16: =ROUND(H413,2) | H16: =ROUND(F16*G16,2) | J16: =ROUND(K414,2) | K16: =ROUND(H16-J16,2) | L16: =IF(H16=0,0,K16/H16) | M16: 600W*1200D*2200H | N16: 低压固定柜
A17: =ROW()-ROW(A$6) | B17: BAN1-07 | C17: 馈线柜 | D17: BlokSeT | E17: 台 | F17: 1 | G17: =ROUND(H446,2) | H17: =ROUND(F17*G17,2) | J17: =ROUND(K447,2) | K17: =ROUND(H17-J17,2) | L17: =IF(H17=0,0,K17/H17) | M17: 800W*1200D*2200H | N17: 低压固定柜
A18: =ROW()-ROW(A$6) | B18: BAN1-08 | C18: 馈线柜 | D18: BlokSeT | E18: 台 | F18: 1 | G18: =ROUND(H476,2) | H18: =ROUND(F18*G18,2) | J18: =ROUND(K477,2) | K18: =ROUND(H18-J18,2) | L18: =IF(H18=0,0,K18/H18) | M18: 600W*1200D*2200H | N18: 低压固定柜
A19: =ROW()-ROW(A$6) | B19: BAN1-09 | C19: 馈线柜 | D19: BlokSeT | E19: 台 | F19: 1 | G19: =ROUND(H511,2) | H19: =ROUND(F19*G19,2) | J19: =ROUND(K512,2) | K19: =ROUND(H19-J19,2) | L19: =IF(H19=0,0,K19/H19) | M19: 600W*1200D*2200H | N19: 低压固定柜
A20: =ROW()-ROW(A$6) | B20: AAN3-01、BAN4-01 | C20: 进线柜 | D20: BlokSeT | E20: 台 | F20: 2 | G20: =ROUND(H546,2) | H20: =ROUND(F20*G20,2) | J20: =ROUND(K547,2) | K20: =ROUND(H20-J20,2) | L20: =IF(H20=0,0,K20/H20) | M20: 700W*1200D*2200H | N20: 低压固定柜
A21: =ROW()-ROW(A$6) | B21: AAN3-02、BAN4-02 | C21: 电容柜 | D21: BlokSeT | E21: 台 | F21: 2 | G21: =ROUND(H574,2) | H21: =ROUND(F21*G21,2) | J21: =ROUND(K575,2) | K21: =ROUND(H21-J21,2) | L21: =IF(H21=0,0,K21/H21) | M21: 800W*1200D*2200H | N21: 低压固定柜
A22: =ROW()-ROW(A$6) | B22: AAN3-03、BAN4-03 | C22: 馈线柜 | D22: BlokSeT | E22: 台 | F22: 2 | G22: =ROUND(H605,2) | H22: =ROUND(F22*G22,2) | J22: =ROUND(K606,2) | K22: =ROUND(H22-J22,2) | L22: =IF(H22=0,0,K22/H22) | M22: 400W*1200D*2200H | N22: 低压固定柜
A23: =ROW()-ROW(A$6) | B23: AAN3-04 | C23: 馈线柜 | D23: BlokSeT | E23: 台 | F23: 1 | G23: =ROUND(H639,2) | H23: =ROUND(F23*G23,2) | J23: =ROUND(K640,2) | K23: =ROUND(H23-J23,2) | L23: =IF(H23=0,0,K23/H23) | M23: 400W*1200D*2200H | N23: 低压固定柜
A24: =ROW()-ROW(A$6) | B24: AAN3-05 | C24: 馈线柜 | D24: BlokSeT | E24: 台 | F24: 1 | G24: =ROUND(H673,2) | H24: =ROUND(F24*G24,2) | J24: =ROUND(K674,2) | K24: =ROUND(H24-J24,2) | L24: =IF(H24=0,0,K24/H24) | M24: 800W*1200D*2200H | N24: 低压固定柜
A25: =ROW()-ROW(A$6) | B25: AAN3-06、BAN4-06 | C25: 馈线柜 | D25: BlokSeT | E25: 台 | F25: 2 | G25: =ROUND(H701,2) | H25: =ROUND(F25*G25,2) | J25: =ROUND(K702,2) | K25: =ROUND(H25-J25,2) | L25: =IF(H25=0,0,K25/H25) | M25: 700W*1200D*2200H | N25: 低压固定柜
A26: =ROW()-ROW(A$6) | B26: AAN3-07、BAN4-07 | C26: 联络柜 | D26: BlokSeT | E26: 台 | F26: 2 | G26: =ROUND(H730,2) | H26: =ROUND(F26*G26,2) | J26: =ROUND(K731,2) | K26: =ROUND(H26-J26,2) | L26: =IF(H26=0,0,K26/H26) | M26: 700W*1200D*2200H | N26: 低压固定柜
A27: =ROW()-ROW(A$6) | B27: BAN4-05 | C27: 馈线柜 | D27: BlokSeT | E27: 台 | F27: 1 | G27: =ROUND(H764,2) | H27: =ROUND(F27*G27,2) | J27: =ROUND(K765,2) | K27: =ROUND(H27-J27,2) | L27: =IF(H27=0,0,K27/H27) | M27: 600W*1200D*2200H | N27: 低压固定柜
A28: =ROW()-ROW(A$6) | B28: BAN4-04 | C28: 馈线柜 | D28: BlokSeT | E28: 台 | F28: 1 | G28: =ROUND(H800,2) | H28: =ROUND(F28*G28,2) | J28: =ROUND(K801,2) | K28: =ROUND(H28-J28,2) | L28: =IF(H28=0,0,K28/H28) | M28: 600W*1200D*2200H | N28: 低压固定柜
A29: =ROW()-ROW(A$6) | B29: AAN5-01、BAN6-01、AAN7-01、BAN8-01 | C29: 进线柜 | D29: BlokSeT | E29: 台 | F29: 4 | G29: =ROUND(H835,2) | H29: =ROUND(F29*G29,2) | J29: =ROUND(K836,2) | K29: =ROUND(H29-J29,2) | L29: =IF(H29=0,0,K29/H29) | M29: 1200W*1200D*2200H | N29: 低压固定柜
A30: =ROW()-ROW(A$6) | B30: AAN5-02、BAN6-02、AAN7-03、BAN8-03 | C30: 电容柜 | D30: BlokSeT | E30: 台 | F30: 4 | G30: =ROUND(H863,2) | H30: =ROUND(F30*G30,2) | J30: =ROUND(K864,2) | K30: =ROUND(H30-J30,2) | L30: =IF(H30=0,0,K30/H30) | M30: 800W*1200D*2200H | N30: 低压固定柜
A31: =ROW()-ROW(A$6) | B31: AAN5-03 | C31: 馈线柜 | D31: BlokSeT | E31: 台 | F31: 1 | G31: =ROUND(H895,2) | H31: =ROUND(F31*G31,2) | J31: =ROUND(K896,2) | K31: =ROUND(H31-J31,2) | L31: =IF(H31=0,0,K31/H31) | M31: 600W*1200D*2200H | N31: 低压固定柜
A32: =ROW()-ROW(A$6) | B32: AAN5-04、BAN6-04、AAN7-04~06、BAN8-05~07 | C32: 馈线柜 | D32: BlokSeT | E32: 台 | F32: 8 | G32: =ROUND(H926,2) | H32: =ROUND(F32*G32,2) | J32: =ROUND(K927,2) | K32: =ROUND(H32-J32,2) | L32: =IF(H32=0,0,K32/H32) | M32: 400W*1200D*2200H | N32: 低压固定柜
A33: =ROW()-ROW(A$6) | B33: AAN5-05 | C33: 馈线柜 | D33: BlokSeT | E33: 台 | F33: 1 | G33: =ROUND(H960,2) | H33: =ROUND(F33*G33,2) | J33: =ROUND(K961,2) | K33: =ROUND(H33-J33,2) | L33: =IF(H33=0,0,K33/H33) | M33: 400W*1200D*2200H | N33: 低压固定柜
A34: =ROW()-ROW(A$6) | B34: AAN5-06、BAN6-06、AAN7-07、BAN8-08 | C34: 馈线柜 | D34: BlokSeT | E34: 台 | F34: 4 | G34: =ROUND(H989,2) | H34: =ROUND(F34*G34,2) | J34: =ROUND(K990,2) | K34: =ROUND(H34-J34,2) | L34: =IF(H34=0,0,K34/H34) | M34: 700W*1200D*2200H | N34: 低压固定柜
A35: =ROW()-ROW(A$6) | B35: AAN5-07、BAN6-07、AAN7-08、BAN8-04 | C35: 馈线柜 | D35: BlokSeT | E35: 台 | F35: 4 | G35: =ROUND(H1017,2) | H35: =ROUND(F35*G35,2) | J35: =ROUND(K1018,2) | K35: =ROUND(H35-J35,2) | L35: =IF(H35=0,0,K35/H35) | M35: 700W*1200D*2200H | N35: 低压固定柜
A36: =ROW()-ROW(A$6) | B36: AAN5-08、BAN6-08、AAN7-02、BAN8-02 | C36: 联络柜 | D36: BlokSeT | E36: 台 | F36: 4 | G36: =ROUND(H1046,2) | H36: =ROUND(F36*G36,2) | J36: =ROUND(K1047,2) | K36: =ROUND(H36-J36,2) | L36: =IF(H36=0,0,K36/H36) | M36: 700W*1200D*2200H | N36: 低压固定柜
A37: =ROW()-ROW(A$6) | B37: BAN6-05 | C37: 馈线柜 | D37: BlokSeT | E37: 台 | F37: 1 | G37: =ROUND(H1080,2) | H37: =ROUND(F37*G37,2) | J37: =ROUND(K1081,2) | K37: =ROUND(H37-J37,2) | L37: =IF(H37=0,0,K37/H37) | M37: 600W*1200D*2200H | N37: 低压固定柜
A38: =ROW()-ROW(A$6) | B38: BAN6-03 | C38: 馈线柜 | D38: BlokSeT | E38: 台 | F38: 1 | G38: =ROUND(H1111,2) | H38: =ROUND(F38*G38,2) | J38: =ROUND(K1112,2) | K38: =ROUND(H38-J38,2) | L38: =IF(H38=0,0,K38/H38) | M38: 600W*1200D*2200H | N38: 低压固定柜
A39: =ROW()-ROW(A$6) | B39: AAN9-01、BAN10-01、AAN11-01、BAN12-01 | C39: 进线柜 | D39: BlokSeT | E39: 台 | F39: 4 | G39: =ROUND(H1146,2) | H39: =ROUND(F39*G39,2) | J39: =ROUND(K1147,2) | K39: =ROUND(H39-J39,2) | L39: =IF(H39=0,0,K39/H39) | M39: 1200W*1200D*2200H | N39: 低压固定柜
A40: =ROW()-ROW(A$6) | B40: AAN9-02、BAN10-02、AAN11-02、BAN12-02 | C40: 联络柜 | D40: BlokSeT | E40: 台 | F40: 4 | G40: =ROUND(H1175,2) | H40: =ROUND(F40*G40,2) | J40: =ROUND(K1176,2) | K40: =ROUND(H40-J40,2) | L40: =IF(H40=0,0,K40/H40) | M40: 700W*1200D*2200H | N40: 低压固定柜
A41: =ROW()-ROW(A$6) | B41: AAN9-03、BAN10-03、AAN11-03、BAN12-03 | C41: 电容柜 | D41: BlokSeT | E41: 台 | F41: 4 | G41: =ROUND(H1203,2) | H41: =ROUND(F41*G41,2) | J41: =ROUND(K1204,2) | K41: =ROUND(H41-J41,2) | L41: =IF(H41=0,0,K41/H41) | M41: 800W*1200D*2200H | N41: 低压固定柜
...
