Workbook

Sheet 项目信息
A1: =T(B22)
A2: =T(B23)
A4: 工程信息
A5: 项目名称 | B5: 项目C-项目询价：202507-017 | E5: 项目编号
A6: 描述 | E6: 报价交期
A7: 报价单号 | B7: DEMO-QUOTE
A8: 报价人 | B8: 报价员B
A9: 创建日期 | B9: 2025.09.10
A10: 报价审核人
A11: 项目负责人
A12: 项目备注
A13: 客户信息
A14: 客户名称
A15: 联系人
A16: 联系电话
A17: 客户地址
A18: 客户邮编
A19: 客户网址
A20: 客户email
A21: 本企业信息
A22: 单位名称 | B22: 某成套设备有限公司
A23: 英文名称
A24: 联系人 | B24: 宋楠 陆洪标
A25: 联系电话 | B25: 13800000000 13800000000
A26: 销售地区
A27: 分类汇总 金额单位：人民币元
A28: 序号 | B28: 分类名称 | C28: 箱柜数量 | D28: 总 价 | E28: 成本 | F28: 毛利 | G28: 毛利率 | H28: 分类属性
A29: =ROW()-ROW(A$28) | B29: =MID(CELL("filename",folderTable9d0678018b5746038ba7e7e139a5b545),SEARCH({"xlsx]",".xls]"},CELL("filename",folderTable9d0678018b5746038ba7e7e139a5b545))+5,31) | C29: =IF(H29="箱变",标段1!F36,标段1!F32*IF(标段1!F36="",1,标段1!F36)) | D29: =ROUND(标段1!H36,2) | E29: =ROUND(标段1!J36,2) | F29: =ROUND((D29-E29),2) | G29: =IF(D29=0,0,F29/D29) | H29: =IF(OR(ISNUMBER(FIND("箱变",B29))=TRUE,ISNUMBER(FIND("欧变",B29))=TRUE,ISNUMBER(FIND("美变",B29))=TRUE,ISNUMBER(FIND("KVA",UPPER(B29)))=TRUE,ISNUMBER(FIND("箱式变电",B29))=TRUE),"箱变","常规")
A30: =ROW()-ROW(A$28)
A31: =ROW()-ROW(A$28)
A32: =ROW()-ROW(A$28)
A33: =ROW()-ROW(A$28)
A34: =ROW()-ROW(A$28)
A35: =ROW()-ROW(A$28)
A36: =ROW()-ROW(A$28)
A37: =ROW()-ROW(A$28)
A38: =ROW()-ROW(A$28)
A39: =ROW()-ROW(A$28)
A40: =ROW()-ROW(A$28)
A41: =ROW()-ROW(A$28)
...

Sheet 标段1
A2: =T(项目信息!B22)
A3: =T(项目信息!B23)
A4: 成套产品报价清单 金额单位：人民币元
A5: =CONCATENATE("项目名称:",项目信息!B5) | H5: =CONCATENATE("报价序号:",项目信息!B7)
A6: 序号 | B6: 柜号 | C6: 箱柜名称 | D6: 箱柜型号 | E6: 单位 | F6: 数量 | G6: 单 价 | H6: 总 价 | I6: 备注 | J6: 成本总价 | K6: 毛利 | L6: 毛利率 | M6: 箱柜尺寸 | N6: 类别 | O6: 预留 | P6: 预留 | Q6: 图号
A7: =ROW()-ROW(A$6) | B7: 1D1 | C7: 进线柜 | D7: Blokset | E7: 台 | F7: 1 | G7: =ROUND(H74,2) | H7: =ROUND(F7*G7,2) | J7: =ROUND(K75,2) | K7: =ROUND(H7-J7,2) | L7: =IF(H7=0,0,K7/H7) | M7: 1100W*1000D*2200H
A8: =ROW()-ROW(A$6) | B8: 1D2 1D3 2D2 2D3 | C8: 电容柜 | D8: Blokset | E8: 台 | F8: 4 | G8: =ROUND(H108,2) | H8: =ROUND(F8*G8,2) | J8: =ROUND(K109,2) | K8: =ROUND(H8-J8,2) | L8: =IF(H8=0,0,K8/H8) | M8: 1000W*1000D*2200H
A9: =ROW()-ROW(A$6) | B9: 1D4 2D4 | C9: 出线柜 | D9: Blokset | E9: 台 | F9: 2 | G9: =ROUND(H150,2) | H9: =ROUND(F9*G9,2) | J9: =ROUND(K151,2) | K9: =ROUND(H9-J9,2) | L9: =IF(H9=0,0,K9/H9) | M9: 600W*1000D*2200H
A10: =ROW()-ROW(A$6) | B10: 1D5 | C10: 出线柜 | D10: Blokset | E10: 台 | F10: 1 | G10: =ROUND(H188,2) | H10: =ROUND(F10*G10,2) | J10: =ROUND(K189,2) | K10: =ROUND(H10-J10,2) | L10: =IF(H10=0,0,K10/H10) | M10: 600W*1000D*2200H
A11: =ROW()-ROW(A$6) | B11: 1D6 | C11: 出线柜 | D11: Blokset | E11: 台 | F11: 1 | G11: =ROUND(H227,2) | H11: =ROUND(F11*G11,2) | J11: =ROUND(K228,2) | K11: =ROUND(H11-J11,2) | L11: =IF(H11=0,0,K11/H11) | M11: 600W*1000D*2200H
A12: =ROW()-ROW(A$6) | B12: 1D7 | C12: 母联柜 | D12: Blokset | E12: 台 | F12: 1 | G12: =ROUND(H256,2) | H12: =ROUND(F12*G12,2) | J12: =ROUND(K257,2) | K12: =ROUND(H12-J12,2) | L12: =IF(H12=0,0,K12/H12) | M12: 900W*1000D*2200H
A13: =ROW()-ROW(A$6) | B13: 2D6 | C13: 出线柜 | D13: Blokset | E13: 台 | F13: 1 | G13: =ROUND(H297,2) | H13: =ROUND(F13*G13,2) | J13: =ROUND(K298,2) | K13: =ROUND(H13-J13,2) | L13: =IF(H13=0,0,K13/H13) | M13: 600W*1000D*2200H
A14: =ROW()-ROW(A$6) | B14: 2D5 | C14: 出线柜 | D14: Blokset | E14: 台 | F14: 1 | G14: =ROUND(H336,2) | H14: =ROUND(F14*G14,2) | J14: =ROUND(K337,2) | K14: =ROUND(H14-J14,2) | L14: =IF(H14=0,0,K14/H14) | M14: 600W*1000D*2200H
A15: =ROW()-ROW(A$6) | B15: 2D1 | C15: 进线柜 | D15: Blokset | E15: 台 | F15: 1 | G15: =ROUND(H367,2) | H15: =ROUND(F15*G15,2) | J15: =ROUND(K368,2) | K15: =ROUND(H15-J15,2) | L15: =IF(H15=0,0,K15/H15) | M15: 900W*1000D*2200H
A16: =ROW()-ROW(A$6) | B16: 3D1 | C16: 进线柜 | D16: Blokset | E16: 台 | F16: 1 | G16: =ROUND(H403,2) | H16: =ROUND(F16*G16,2) | J16: =ROUND(K404,2) | K16: =ROUND(H16-J16,2) | L16: =IF(H16=0,0,K16/H16) | M16: 700W*1000D*2200H
A17: =ROW()-ROW(A$6) | B17: 3D2 | C17: 电容柜 | D17: Blokset | E17: 台 | F17: 1 | G17: =ROUND(H435,2) | H17: =ROUND(F17*G17,2) | J17: =ROUND(K436,2) | K17: =ROUND(H17-J17,2) | L17: =IF(H17=0,0,K17/H17) | M17: 1000W*1000D*2200H
A18: =ROW()-ROW(A$6) | B18: 3D3 4D3 4D4 | C18: 电容柜 | D18: Blokset | E18: 台 | F18: 3 | G18: =ROUND(H466,2) | H18: =ROUND(F18*G18,2) | J18: =ROUND(K467,2) | K18: =ROUND(H18-J18,2) | L18: =IF(H18=0,0,K18/H18) | M18: 1000W*1000D*2200H
A19: =ROW()-ROW(A$6) | B19: 3D4 4D5 | C19: 出线柜 | D19: Blokset | E19: 台 | F19: 2 | G19: =ROUND(H507,2) | H19: =ROUND(F19*G19,2) | J19: =ROUND(K508,2) | K19: =ROUND(H19-J19,2) | L19: =IF(H19=0,0,K19/H19) | M19: 600W*1000D*2200H
A20: =ROW()-ROW(A$6) | B20: 3D5 4D6 | C20: 出线柜 | D20: Blokset | E20: 台 | F20: 2 | G20: =ROUND(H550,2) | H20: =ROUND(F20*G20,2) | J20: =ROUND(K551,2) | K20: =ROUND(H20-J20,2) | L20: =IF(H20=0,0,K20/H20) | M20: 600W*1000D*2200H
A21: =ROW()-ROW(A$6) | B21: 3D6 4D7 | C21: 出线柜 | D21: Blokset | E21: 台 | F21: 2 | G21: =ROUND(H591,2) | H21: =ROUND(F21*G21,2) | J21: =ROUND(K592,2) | K21: =ROUND(H21-J21,2) | L21: =IF(H21=0,0,K21/H21) | M21: 600W*1000D*2200H
A22: =ROW()-ROW(A$6) | B22: 3D7 | C22: 出线柜 | D22: Blokset | E22: 台 | F22: 1 | G22: =ROUND(H632,2) | H22: =ROUND(F22*G22,2) | J22: =ROUND(K633,2) | K22: =ROUND(H22-J22,2) | L22: =IF(H22=0,0,K22/H22) | M22: 600W*1000D*2200H
A23: =ROW()-ROW(A$6) | B23: 3D8 | C23: 出线柜 | D23: Blokset | E23: 台 | F23: 1 | G23: =ROUND(H676,2) | H23: =ROUND(F23*G23,2) | J23: =ROUND(K677,2) | K23: =ROUND(H23-J23,2) | L23: =IF(H23=0,0,K23/H23) | M23: 800W*1000D*2200H
A24: =ROW()-ROW(A$6) | B24: 3D9 4D10 | C24: 出线柜 | D24: Blokset | E24: 台 | F24: 2 | G24: =ROUND(H720,2) | H24: =ROUND(F24*G24,2) | J24: =ROUND(K721,2) | K24: =ROUND(H24-J24,2) | L24: =IF(H24=0,0,K24/H24) | M24: 800W*1000D*2200H
A25: =ROW()-ROW(A$6) | B25: 3D10 | C25: 出线柜 | D25: Blokset | E25: 台 | F25: 1 | G25: =ROUND(H757,2) | H25: =ROUND(F25*G25,2) | J25: =ROUND(K758,2) | K25: =ROUND(H25-J25,2) | L25: =IF(H25=0,0,K25/H25) | M25: 600W*1000D*2200H
A26: =ROW()-ROW(A$6) | B26: 4D1 | C26: 进线柜 | D26: Blokset | E26: 台 | F26: 1 | G26: =ROUND(H791,2) | H26: =ROUND(F26*G26,2) | J26: =ROUND(K792,2) | K26: =ROUND(H26-J26,2) | L26: =IF(H26=0,0,K26/H26) | M26: 700W*1000D*2200H
A27: =ROW()-ROW(A$6) | B27: 4D2 | C27: 母联柜 | D27: Blokset | E27: 台 | F27: 1 | G27: =ROUND(H823,2) | H27: =ROUND(F27*G27,2) | J27: =ROUND(K824,2) | K27: =ROUND(H27-J27,2) | L27: =IF(H27=0,0,K27/H27) | M27: 700W*1000D*2200H
A28: =ROW()-ROW(A$6) | B28: 4D8 | C28: 出线柜 | D28: Blokset | E28: 台 | F28: 1 | G28: =ROUND(H867,2) | H28: =ROUND(F28*G28,2) | J28: =ROUND(K868,2) | K28: =ROUND(H28-J28,2) | L28: =IF(H28=0,0,K28/H28) | M28: 600W*1000D*2200H
A29: =ROW()-ROW(A$6) | B29: 4D9 | C29: 出线柜 | D29: Blokset | E29: 台 | F29: 1 | G29: =ROUND(H913,2) | H29: =ROUND(F29*G29,2) | J29: =ROUND(K914,2) | K29: =ROUND(H29-J29,2) | L29: =IF(H29=0,0,K29/H29) | M29: 800W*1000D*2200H
A30: =ROW()-ROW(A$6) | B30: 4D11 | C30: 出线柜 | D30: Blokset | E30: 台 | F30: 1 | G30: =ROUND(H953,2) | H30: =ROUND(F30*G30,2) | J30: =ROUND(K954,2) | K30: =ROUND(H30-J30,2) | L30: =IF(H30=0,0,K30/H30) | M30: 600W*1000D*2200H
A31: =ROW()-ROW(A$6)
A32: =ROW()-ROW(A$6) | B32: 小计 | E32: 台 | F32: =SUM(F6:INDEX(F:F,ROW()-1)) | H32: =ROUND(SUM(H6:INDEX(H:H,ROW()-1)),2) | J32: =ROUND(SUM(J6:INDEX(J:J,ROW()-1)),2) | K32: =ROUND(SUM(K6:INDEX(K:K,ROW()-1)),2)
A33: =ROW()-ROW(A$6) | B33: 包装费 | E33: 台 | F33: 34 | G33: 100 | H33: =ROUND(F33*G33,2) | J33: =ROUND(H33,2)
A34: =ROW()-ROW(A$6) | B34: 运输费 | E34: 套 | F34: 1 | G34: 5800 | H34: =ROUND(F34*G34,2) | J34: =ROUND(H34,2)
A35: =ROW()-ROW(A$6) | B35: 运载工具车 | E35: 台 | F35: 1 | G35: 0 | H35: =ROUND(F35*G35,2) | J35: =ROUND(H35,2)
A36: =ROW()-ROW(A$6) | B36: 合计(人民币大写) | C36: =TEXT(SUBSTITUTE(IF(H36="","",IF(MOD(H36,1)=0,TEXT(INT(H36),"[DBNum2][$-804]G/通用格式元整"),(TEXT(INT(H36),"[DBNum2][$-804]G/通用格式元")&TEXT((INT(H36*10)-INT(H36)*10),"[DBNum2][$-804]G/通用格式角")&TEXT((INT(H36*100)-INT(H36*10)*10),"[DBNum2][$-804]G/通用格式分")))),"零角","零"),) | F36: =IF(项目信息!H29="箱变",1,"") | G36: =ROUND(SUM(H32:H35),2) | H36: =ROUND(IF(F36="",1,F36)*G36,2) | J36: =ROUND(IF(F36="",1,F36)*SUM(J32:J35),2) | K36: =ROUND(IF(F36="",1,F36)*SUM(K32:K35),2) | L36: =IF(H36=0,0,K36/H36) | R36: 17.71 | S36: =ROUND(R36*H36,0)
A37: 说明
A41: =CONCATENATE("报价人：",项目信息!B8) | H41: =项目信息!B9
A42: =T(项目信息!$B$22)
A43: =T(项目信息!$B$23)
A44: 成套产品报价明细表
...
